Workbook

Sheet Cover
B11: Regal Rexnord - Altra
B13: Accretion Dilution Model
B15: Date completed: 9/3/2026
B16: Analysis performed using data available on 3/1/23
B18: By: Tyler Spencer
B20: Is this deal accretive or dilutive? | C20: per share | D20: % per share
B21: ="Is "&IF('Accretion Dilution'!M38>0,"accretive","dilutive")&" on a GAAP basis" -> Is dilutive on a GAAP basis | C21: ='Accretion Dilution'!M38 -> -0.67907887 | D21: ='Accretion Dilution'!M39 -> -0.093152108
B22: ="Is "&IF('Accretion Dilution'!N38>0,"accretive","dilutive")&" on a cash basis" -> Is accretive on a cash basis | C22: ='Accretion Dilution'!N38 -> 0.56788436 | D22: ='Accretion Dilution'!N39 -> 0.077899089
B23: ="Is "&IF('Accretion Dilution'!N39>0,"accretive","dilutive")&" on an adjusted basis" -> Is accretive on an adjusted basis | C23: ='Accretion Dilution'!O38 -> 1.0608731 | D23: ='Accretion Dilution'!O39 -> 0.10289554
B24: Cash/ adjusted EPS accretive; GAAP breaks even at +$56.5mm synergies
B26: Legend
B27: Blue | C27: Hardcoded input
B28: Green | C28: Direct cross-tab reference only (e.g. =Assumptions!N9). Formulas that compute using another tab's inputs stay black.
B29: Black | C29: Formula computed (same tab or across tabs), all labels, and data table outputs
B30: Red | C30: Link to an external file
B32: Blue is also used for Pro Forma BS cells that sum raw 10-K line items (inputs in substance); see cell comments for the components.

Sheet Summary
B2: =Cover!B11 -> Regal Rexnord - Altra
B3: Summary
B4: (In millions, except per share data)
B6: DEAL TERMS | G6: PRO FORMA — FY22 , FULL RUN-RATE SYNERGIES | J6: GAAP | K6: Cash | L6: Adjusted
B7: Offer price per share | E7: =Assumptions!H26 -> 62 | G7: Pro forma net income | J7: ='Accretion Dilution'!M33 -> 443.35793 | K7: ='Accretion Dilution'!N33 -> 526.98486 | L7: ='Accretion Dilution'!O33 -> 762.59469
B8: Consideration / structure | E8: =TEXT(Assumptions!H29,"0%")&" Cash" -> 100% Cash | G8: Pro forma diluted shares | J8: ='Accretion Dilution'!M34 -> 67.064472 | K8: ='Accretion Dilution'!N34 -> 67.064472 | L8: ='Accretion Dilution'!O34 -> 67.064472
B9: Premium to unaffected (10/26/22) | E9: =Assumptions!H25 -> 0.53999006 | G9: Pro forma EPS | J9: =J7/J8 -> 6.6109211 | K9: =K7/K8 -> 7.8578844 | L9: =L7/L8 -> 11.371068
B10: Equity value (offer) | E10: =Assumptions!H27 -> 4101.3399 | G10: Acquirer standalone EPS | J10: ='Accretion Dilution'!M37 -> 7.29 | K10: ='Accretion Dilution'!N37 -> 7.29 | L10: ='Accretion Dilution'!O37 -> 10.310195
B11: Enterprise value (offer) | E11: =Assumptions!H27+'Pro Forma BS'!I40 -> 4936.9399 | G11: Accretion / (dilution) $ | J11: =J9-J10 -> -0.67907887 | K11: =K9-K10 -> 0.56788436 | L11: =L9-L10 -> 1.0608731
B12: EV / CY2022 Adjusted EBITDA | E12: =E11/'Pro Forma BS'!I44 -> 12.707696 | G12: Accretion / (dilution) % | J12: =J11/J10 -> -0.093152108 | K12: =K11/K10 -> 0.077899089 | L12: =L11/L10 -> 0.10289554
G13: Add'l pretax synergies to breakeven | J13: =MAX(0,-(J11*J8/(1-Assumptions!H64))) -> 56.503803 | K13: =MAX(0,-(K11*K8/(1-Assumptions!H64))) -> 0 | L13: =MAX(0,-(L11*L8/(1-Assumptions!H64))) -> 0
B15: FINANCING | G15: RECONCILIATION vs. DISCLOSED
B16: Total new debt raised | E16: =Assumptions!H51 -> 4892.9115 | I16: Model | J16: Disclosed | K16: Diff | L16: % Diff
B17: Blended rate on new debt | E17: =Assumptions!H56 -> 0.062 | G17: Goodwill created | I17: =Assumptions!N56 -> 2695.6824 | J17: 2614.6 | K17: =I17-J17 -> 81.082426 | L17: =K17/J17 -> 0.031011407
B18: Pro forma gross debt | E18: ='Pro Forma BS'!N36 -> 6916.4115 | G18: Offer value (equity) | I18: =Assumptions!H27 -> 4101.3399 | J18: 4110 | K18: =I18-J18 -> -8.660074 | L18: =K18/J18 -> -0.002107074
B19: Pro forma net debt | E19: ='Pro Forma BS'!N40 -> 6422.5321
B20: PF gross debt / Adjusted EBITDA | E20: ='Pro Forma BS'!N46 -> 4.6103263
B21: PF net debt / synerg. Adjusted EBITDA | E21: ='Pro Forma BS'!N40/'Pro Forma BS'!N45 -> 3.8685292
B22: Target leverage (mgmt) | E22: 2.5x – 3.0x
B24: FY2022 basis, full run-rate synergies. GAAP EPS includes incremental D&A and financing-fee amortization. Cash EPS excludes incremental D&A and financing-fee amortization.
B25: Adjusted EPS adds back all intangible amortization (acquirer + target), restructuring, and transaction/deal costs (management-adjusted basis; retains incremental depreciation
B26: and financing-fee amortization); standalone acquirer EPS adjusted on the same basis. Blue = disclosed reference.

Sheet Assumptions
B2: =Cover!B11 -> Regal Rexnord - Altra
B3: Assumptions
B4: (In millions, except per share data)
C6: ACQUIRER | J6: SOURCES
C7: Name | H7: Regal Rexnord Corporation | J7: New borrowing to acquire target | N7: =H45 -> 3732.2193
C8: Ticker | H8: RRX | J8: New borrowing to refinance target debt | N8: =H50 -> 1044.5
C9: Latest filing date | H9: 44981 | J9: Cash used to acquire target | N9: =H46 -> 369.12059
C10: Filing type | H10: 10-K | J10: Value of stock issued to acquire target | N10: =H28*H27 -> 0
C11: Current share price | H11: 149.66 | J11: New borrowing to fund fees | N11: =H54+H61 -> 116.1922
C12: Diluted shares outstanding (MM) | H12: =Shares!N15 -> 66.811716 | J12: Total sources | N12: =SUM(N7:N11) -> 5262.0321
C13: Equity value | H13: =H11*H12 -> 9999.0414
C15: TARGET | J15: USES
C16: Name | H16: Altra Industrial Motion Corp | J16: Stock to target | N16: =H28*H27 -> 0
C17: Ticker | H17: AIMC | J17: Cash to target | N17: =H29*H27 -> 4101.3399
C18: Latest filing date | H18: 44986 | J18: Target debt refinanced | N18: =IF(H48="Refinanced",H50,0) -> 1044.5
C19: Filing type | H19: 10-K | J19: Deal fees (advisory, legal, and accounting) | N19: =H61 -> 61.520099
C20: Unaffected share price (10/26/22) | H20: 40.26 | J20: Financing fees (related to acq debt) | N20: =H54 -> 54.672106
C21: Diluted shares outstanding (MM) | H21: =Shares!J15 -> 66.150644 | J21: Total Uses | N21: =SUM(N16:N20) -> 5262.0321
J22: Do sources equal uses? | N22: =IF(N21=N12,"OK",N21-N12) -> OK
C24: DEAL STRUCTURE | J24: ASSET ADJUSTMENTS
C25: % Offer premium | H25: =H26/H20-1 -> 0.53999006 | J25: Tangible assets
C26: Offer price per share | H26: ='Accretion Dilution'!E47 -> 62 | J26: Book value of target PP&E | N26: 275.1
C27: Offer value | H27: =H21*H26 -> 4101.3399 | J27: % Write-up | N27: 0.3
C28: % Stock | H28: 0 | J28: Asset write-up | N28: =N26*N27 -> 82.53
C29: % Cash | H29: =1-H28 -> 1 | J29: Useful life | N29: 15
C30: Tax structure | H30: Stock Sale | J30: Incremental depreciation expense | N30: =N28/N29 -> 5.502
C31: Acquirer shares issued (MM) | H31: =IFERROR(H28*(H27/H11),0) -> 0 | J31: Incremental deferred tax liabilities | N31: =IF(H30="Stock Sale",N28*H63,0) -> 20.6325
C32: Nominal exchange ratio | H32: =IFERROR(H26/H11,0) -> 0.41427235
C33: Actual exchange ratio | H33: =IFERROR(H28*(H26/H11),0) -> 0 | J33: Intangible assets
J34: Book value of target intangible assets | N34: 970.4
J35: % Write-up | N35: 1.2
J36: Asset write-up | N36: =N35*N34 -> 1164.48
J37: Useful life | N37: 13
J38: Incremental amortization expense | N38: =N36/N37 -> 89.575385
J39: Incremental deferred tax liabilities | N39: =IF(H30="Stock Sale",N36*H63,0) -> 291.12
C41: FINANCING | J41: PURCHASE PRICE ALLOCATION
C42: % Cash consideration from debt | H42: ='Accretion Dilution'!E48 -> 0.91 | J42: Target assets - book value | N42: 3676.6
C43: % Cash consideration from excess cash | H43: =1-H42 -> 0.09 | J43: Plus: PP&E write ups | N43: =N28 -> 82.53
C44: Acquirer available cash | H44: 688.5 | J44: Plus: Intangible asset write ups | N44: =N36 -> 1164.48
C45: Acquirer new borrowing | H45: =H42*H29*H27 -> 3732.2193 | J45: Less: Write off of target goodwill | N45: -1524.5
...

Sheet Pro Forma BS
B2: =Cover!B11 -> Regal Rexnord - Altra
B3: Pro Forma Statements
B4: (In millions, except per share data)
H5: Standalone | K5: Adjustments | N5: Pro forma
H6: Acquirer | I6: Target
B7: Assets | H7: =Assumptions!H9 -> 44981 | I7: =Assumptions!H18 -> 44986 | K7: Increase | L7: Decrease
C8: Cash & equivalents | H8: 688.5 | I8: 208.9 | L8: =-Assumptions!N9 -> -369.12059 | N8: =SUM(H8:M8) -> 528.27941
C9: Accounts receivable | H9: 797.4 | I9: 244.6 | N9: =SUM(H9:M9) -> 1042
C10: Inventory | H10: 1336.9 | I10: 338.9 | N10: =SUM(H10:M10) -> 1675.8
C11: Deferred tax assets | H11: 43.9 | I11: 7.5 | L11: =Assumptions!N46 -> -7.5 | N11: =SUM(H11:M11) -> 43.9
C12: Other current assets | H12: =150.9+17+9.8 -> 177.7 | I12: 35.1 | N12: =SUM(H12:M12) -> 212.8
C13: PP&E | H13: 807 | I13: 275.1 | K13: =Assumptions!N28 -> 82.53 | N13: =SUM(H13:M13) -> 1164.63
C14: Intangible assets | H14: 2229.9 | I14: 970.4 | K14: =Assumptions!N36 -> 1164.48 | N14: =SUM(H14:M14) -> 4364.78
C15: Goodwill | H15: 4018.8 | I15: 1524.5 | K15: =Assumptions!N56 -> 2695.6824 | L15: =Assumptions!N45 -> -1524.5 | N15: =SUM(H15:M15) -> 6714.4824
C16: Other assets | H16: =110.9+57.9 -> 168.8 | I16: =21.3+41.4+8.9 -> 71.6 | K16: =Assumptions!N20 -> 54.672106 | N16: =SUM(H16:M16) -> 295.07211
B17: Total Assets | H17: =SUM(H8:H16) -> 10268.9 | I17: =SUM(I8:I16) -> 3676.6 | N17: =SUM(N8:N16) -> 16041.744
B19: Liabilities & Equity
C20: Accounts payable | H20: 497.7 | I20: 165.8 | N20: =SUM(H20:M20) -> 663.5
C21: Accrued expenses & def. revenue | H21: =23.2+141.1+280+26.4 -> 470.7 | I21: =67.9+88.4+22.4+12.4 -> 191.1 | N21: =SUM(H21:M21) -> 661.8
C22: Revolver & current debt | H22: 33.8 | I22: 20.4 | L22: =IF(Assumptions!$H$48="Refinanced",-I22,0) -> -20.4 | N22: =SUM(H22:M22) -> 33.8
C23: Long term debt | H23: 1989.7 | I23: 1024.1 | K23: =Assumptions!N7+Assumptions!N8+Assumptions!N11 -> 4892.9115 | L23: =IF(Assumptions!$H$48="Refinanced",-I23,0) -> -1024.1 | N23: =SUM(H23:M23) -> 6882.6115
C24: Convertible debt | H24: 0 | I24: 0 | N24: =SUM(H24:M24) -> 0
C25: Deferred tax liabilities | H25: 591.9 | I25: 216.8 | K25: =Assumptions!N51 -> 311.7525 | L25: =Assumptions!N50 -> 0 | N25: =SUM(H25:M25) -> 1120.4525
C26: Other liabilities | H26: =97.6+88.1+76.8 -> 262.5 | I26: =17.3+1.8+6.3+30.6 -> 56 | N26: =SUM(H26:M26) -> 318.5
C27: Preferred stock | H27: 0 | I27: 0 | N27: =SUM(H27:M27) -> 0
C28: Noncontrolling interests | H28: 34.4 | I28: 0 | N28: =SUM(H28:M28) -> 34.4
C29: Shareholders equity | H29: 6388.2 | I29: 2002.4 | K29: =Assumptions!N16 -> 0 | L29: =-(I29+Assumptions!N19) -> -2063.9201 | N29: =SUM(H29:M29) -> 6326.6799
B30: Total Liabilities & Equity | H30: =SUM(H20:H29) -> 10268.9 | I30: =SUM(I20:I29) -> 3676.6 | N30: =SUM(N20:N29) -> 16041.744
C31: Balance Check | H31: =IF(ABS(H30-H17)<0.0001,"OK",H30-H17) -> OK | I31: =IF(ABS(I30-I17)<0.0001,"OK",I30-I17) -> OK | N31: =IF(ABS(N30-N17)<0.0001,"OK",N30-N17) -> OK
H34: Standalone | N34: Pro forma
B35: Credit Statistics | H35: Acquirer | I35: Target
C36: Total debt | H36: =H23+H24+H22 -> 2023.5 | I36: =I23+I24+I22 -> 1044.5 | N36: =N23+N24+N22 -> 6916.4115
C37: + Noncontrolling interests | H37: =H28 -> 34.4 | I37: =I28 -> 0 | N37: =N28 -> 34.4
C38: + Preferred stock | H38: =H27 -> 0 | I38: =I27 -> 0 | N38: =N27 -> 0
C39: - Cash & equivalents | H39: =-H8 -> -688.5 | I39: =-I8 -> -208.9 | N39: =-N8 -> -528.27941
C40: Net debt | H40: =SUM(H36:H39) -> 1369.4 | I40: =SUM(I36:I39) -> 835.6 | N40: =SUM(N36:N39) -> 6422.5321
C42: Equity value (share price x shares out.) | H42: =Assumptions!H11*Shares!N15 -> 9999.0414 | I42: =Assumptions!H20*Shares!J15 -> 2663.2249 | N42: =Assumptions!H11*Shares!N15 -> 9999.0414
C43: Enterprise value | H43: =H42+H40 -> 11368.441 | I43: =I42+I40 -> 3498.8249 | N43: =N42+N40 -> 16421.574
C44: ="Adjusted EBITDA for the calendar year ending 2022" -> Adjusted EBITDA for the calendar year ending 2022 | H44: =Assumptions!N60 -> 1111.7 | I44: =Assumptions!N61 -> 388.5 | N44: =SUM(H44:I44) -> 1500.2
C45: ="Synergized Adjusted EBITDA for the calendar year ending 2022" -> Synergized Adjusted EBITDA for the calendar year ending 2022 | N45: =N44+Assumptions!H62 -> 1660.2
...

Sheet Accretion Dilution
B2: =Cover!B11 -> Regal Rexnord - Altra
B3: Accretion Dilution Analysis
B4: (In millions, except per share data)
C6: EPS Accounting: | M6: GAAP EPS | N6: Cash EPS | O6: Adjusted EPS
C7: Year Ended | M7: 44926 | N7: 44926 | O7: 44926
C9: Acquirer
D10: Net income | M10: 488.9 | N10: 488.9 | O10: 488.9
D11: EPS | M11: 7.29 | N11: 7.29 | O11: 7.29
D12: Diluted shares outstanding (weighted avg.) | M12: =M10/M11 -> 67.064472 | N12: =N10/N11 -> 67.064472 | O12: =O10/O11 -> 67.064472
C13: Target
D14: Net income | M14: 127 | N14: 127 | O14: 127
D15: EPS | M15: 1.94 | N15: 1.94 | O15: 1.94
D16: Diluted shares outstanding (weighted avg.) | M16: =M14/M15 -> 65.463918 | N16: =N14/N15 -> 65.463918 | O16: =O14/O15 -> 65.463918
C18: Transaction related expenses/income(1)
D19: Less: Interest expense from new deal debt | M19: =-Assumptions!$H$56 * 'Pro Forma BS'!$K$23 -> -303.36052 | N19: =-Assumptions!$H$56 * 'Pro Forma BS'!$K$23 -> -303.36052 | O19: =-Assumptions!$H$56 * 'Pro Forma BS'!$K$23 -> -303.36052
D20: Plus: Target interest expense eliminated | M20: =Assumptions!$H$66 -> 51.5 | N20: =Assumptions!$H$66 -> 51.5 | O20: =Assumptions!$H$66 -> 51.5
D21: Less: Interest income on cash forgone | M21: =Assumptions!$H$57*'Pro Forma BS'!$L$8 -> -18.45603 | N21: =Assumptions!$H$57*'Pro Forma BS'!$L$8 -> -18.45603 | O21: =Assumptions!$H$57*'Pro Forma BS'!$L$8 -> -18.45603
D22: Plus: Synergies | M22: =Assumptions!$H$62 -> 160 | N22: =Assumptions!$H$62 -> 160 | O22: =Assumptions!$H$62 -> 160
D23: Less: Incremental depreciation expense | M23: =-(Assumptions!N30) -> -5.502 | N23: 0 | O23: =-(Assumptions!N30) -> -5.502
D24: Less: Incremental amortization expense | M24: =-(Assumptions!N38) -> -89.575385 | N24: 0 | O24: 0
D25: Less: Financing fee amortization | M25: =-Assumptions!$H$55 -> -8.678112 | N25: 0 | O25: =-Assumptions!$H$55 -> -8.678112
D26: Plus: Acquirer intangible amortization | M26: 0 | N26: 0 | O26: =Assumptions!N62 -> 185.5
D27: Plus: Target intangible amortization | M27: 0 | N27: 0 | O27: =Assumptions!N63 -> 55.2
D28: Plus: Restructuring and related costs | M28: 0 | N28: 0 | O28: =Assumptions!N64 -> 46.8
D29: Plus: Transaction and related costs | M29: 0 | N29: 0 | O29: =Assumptions!N65 -> 19
D30: Taxes (assumed at acquirer's rate) | M30: =-(SUM(M19:M25)*Assumptions!$H$64) -> 41.529976 | N30: =-(SUM(N19:N25)*Assumptions!$H$64) -> 21.40141 | O30: =-(SUM(O19:O29)*Assumptions!$H$64) -> -35.308649
D31: Total after tax transaction related income/ (expenses) | M31: =SUM(M19:M30) -> -172.54207 | N31: =SUM(N19:N30) -> -88.915135 | O31: =SUM(O19:O30) -> 146.69469
D33: Pro Forma Net Income | M33: =M31+M14+M10 -> 443.35793 | N33: =N31+N14+N10 -> 526.98486 | O33: =O31+O14+O10 -> 762.59469
D34: Pro Forma Shares Outstanding | M34: =M12+Assumptions!$H$31 -> 67.064472 | N34: =N12+Assumptions!$H$31 -> 67.064472 | O34: =O12+Assumptions!$H$31 -> 67.064472
C36: Pro forma EPS | M36: =M33/M34 -> 6.6109211 | N36: =N33/N34 -> 7.8578844 | O36: =O33/O34 -> 11.371068
C37: Acquirer standalone EPS | M37: =M11 -> 7.29 | N37: =N11 -> 7.29 | O37: =O11 + (Assumptions!N62+Assumptions!N64+Assumptions!N65)*(1-Assumptions!H64)/O12 -> 10.310195
C38: Accretion / Dilution per share | M38: =M36-M37 -> -0.67907887 | N38: =N36-N37 -> 0.56788436 | O38: =O36-O37 -> 1.0608731
C39: Accretion / Dilution % | M39: =M38/M37 -> -0.093152108 | N39: =N38/N37 -> 0.077899089 | O39: =O38/O37 -> 0.10289554
C40: Additional pretax synergies required to breakeven | M40: =MAX(0,-(M38*M34/(1-Assumptions!$H$64))) -> 56.503803 | N40: =MAX(0,-(N38*N34/(1-Assumptions!$H$64))) -> 0 | O40: =MAX(0,-(O38*O34/(1-Assumptions!$H$64))) -> 0
B43: Sensitivity Analysis
B45: Annualized synergies | E45: 160
B46: Interest rate on new debt | E46: 0.062
B47: Offer Price | E47: 62
B48: % debt used in merger | E48: 0.91
D50: GAAP EPS Accretion / Dilution Per Share | L50: GAAP EPS Accretion / Dilution Per Share
...

Sheet Shares
B2: =Cover!B11 -> Regal Rexnord - Altra
B3: Shares
B4: (In millions, except per share data)
G6: Target | K6: Acquirer
G7: =Assumptions!H16 -> Altra Industrial Motion Corp | K7: =Assumptions!H7 -> Regal Rexnord Corporation
B8: Current share price | J8: =Assumptions!H26 -> 62 | N8: =Assumptions!H11 -> 149.66
B9: Basic shares outstanding (most recent filing) | J9: 65.357 | N9: 66.231072
B10: + Additional shares from options | J10: =I20 -> 0.6762 | N10: =M20 -> 0.80814
B11: - Shares repurchased under treasury stock method | J11: =-(J20/J8) -> -0.44465603 | N11: =-(N20/N8) -> -0.5018611
B12: + Unvested RSUs | J12: 0.5621 | N12: 0.274365
B13: + Additional shares from convertible debt | J13: 0 | N13: 0
B14: + Additional shares from convertible stock | J14: 0 | N14: 0
B15: Diluted shares outstanding | J15: =SUM(J9:J14) -> 66.150644 | N15: =SUM(N9:N14) -> 66.811716
B17: Options | G17: # Outstanding | H17: Strike Price | I17: Include? | J17: Proceeds | K17: # Exercisable | L17: Strike Price | M17: Include? | N17: Proceeds
B18: Tranche 1 | G18: 0.6762 | H18: 40.77 | I18: =IF(H18<J8,G18,0) -> 0.6762 | J18: =I18*H18 -> 27.568674 | K18: 0.80814 | L18: 92.94 | M18: =IF(L18<N8,K18,0) -> 0.80814 | N18: =M18*L18 -> 75.108532
B19: Tranche 2
B20: Total | I20: =SUM(I18:I19) -> 0.6762 | J20: =SUM(J18:J19) -> 27.568674 | M20: =SUM(M18:M19) -> 0.80814 | N20: =SUM(N18:N19) -> 75.108532

Sheet Data Sources
B2: Regal Rexnord – Altra
B3: Sources
C4: Primary sources are company SEC filings (10-K, 8-K) and market data as of the modeling date (3/1/2023) except where noted as an estimate. Each figure is also documented in a cell comment on the relevant model tab.
B6: Regal Rexnord (Acquirer) — Company Financials & Market Data
B8: Regal Rexnord Corporation FY2022 Form 10-K (SEC EDGAR, period ended 12/31/2022)
C9: Adjusted EBITDA = $1,111.7mm, Regal Rexnord adjusted EBITDA per the Net Income to Adjusted EBITDA reconciliation in the Q4 2022 earnings release, 2/1/23. See Assumptions!N60.
C10: Intangible amortization, FY22 = $185.5mm (Note 5, printed p.77). See Assumptions!N62.
C11: Restructuring & related costs, FY22 = $46.8mm (Note 15, printed p.105). See Assumptions!N64.
C12: Transaction & related costs, FY22 = $19.0mm ($14.7mm Altra + $4.3mm Rexnord; MD&A, printed p.66). See Assumptions!N65.
C13: Balance-sheet line-item groupings for the pro forma (prepaid/other assets, accrued liabilities, other liabilities). See Pro Forma BS!H12, H16, H21, H26.
B15: Regal Rexnord (NYSE: RRX) — market close share price $149.66 as of 2/24/2023
C16: Current acquirer share price used for equity value and diluted-share (treasury method) calculations. See Assumptions!H11.
B18: Altra Industrial Motion (Target) — Company Financials
B20: Altra Industrial Motion Corp FY2022 Form 10-K (SEC EDGAR, period ended 12/31/2022)
B21: Altra Industrial Motion Corp Q4 & FY2022 earnings release (dated 3/1/2023 4:47pm ET; uploaded document) | C21: Altra adjusted EBITDA = $388.5mm, FY2022 Non-GAAP Adjusted EBITDA disclosed directly in Altra's Q4 & FY2022 earnings release (Reconciliation of Non-GAAP Adjusted EBITDA, Year Ended 12/31/2022); on the same footing as Regal's (both add back stock compensation). The announced ~13.1x target multiple reconciles off LTM Q3 2022 (deal announced 10/26/22): FY2022 $388.5 less Q4 2022 $96.2 plus Q4 2021 $87.2 = $379.5mm LTM, or 13.01x against the $4,936.9mm offer EV (13.04x vs. management's stated ~$4.95bn) — an inference from published quarters, not a disclosure. Release dated 3/1/2023 4:47pm ET, after the close on the modeling date. See Assumptions!N61.
C22: Amortization of intangibles = $55.2mm (consolidated statement of cash flows). See Assumptions!N63.
C23: Interest expense, net = $51.5mm for FY2022 (consolidated statement of earnings, p.48; also MD&A p.50). See Assumptions!H66.
C24: Balance-sheet line-item groupings for the pro forma (deferred taxes/other assets, accrued liabilities, other liabilities). See Pro Forma BS!I16, I21, I26.
B26: Altra Industrial Motion (NASDAQ: AIMC) — unaffected share price $40.26 as of 10/26/2022
C27: Unaffected (pre-announcement) target share price; the $62.00 offer implies a ~54.0% premium. Source: Yahoo Finance, 10/27/2022 (included in source documents). See Assumptions!H20, H25, H26.
B29: Deal Financing Terms
B31: Regal Rexnord Form 8-K, filed 1/9/2023 — debt issuance terms
C32: Principal-weighted average coupon of 6.2% on acquisition financing, applied to the full $4,891.7mm including term-loan borrowings. See Assumptions!H56.
B34: Regal Rexnord Form 8-K, filed 1/24/2023 — notes offering
C35: Principal-weighted average tenor of 6.3 years across the four note tranches. See Assumptions!H52.
C36: Financing fees of ~1.13% implied from $4,700mm gross vs. ~$4,647mm net proceeds. See Assumptions!H53.
B38: Modeling Estimates & Methodology
B40: Analyst estimates (no external source — modeling judgment)
C41: Yield earned on cash = 5.0% (estimate). See Assumptions!H57.
C42: Deal fees = 1.5% of offer value (estimate; RRX recorded $14.7mm of transaction costs in 2022, the $86.9mm 2023 figure was not knowable at the modeling date). See Assumptions!H60.
C43: DTL calculation tax rate = 25% (used for incremental DTLs on Altra's FDII credits from overseas operations). See Assumptions!H63.
B45: Methodology notes
C46: Options are consolidated to a weighted average per company; neither company discloses tranche-by-tranche data. See Shares!B18.
C47: Pro forma cash EPS is not an adjusted-EPS figure and deviates from management's adjusted cash EPS. See Accretion Dilution!N36.
C48: Sensitivity data-table inputs (synergies $160mm, rate 6.2%) are set on the Accretion Dilution tab to feed the Excel data tables. See Accretion Dilution!E45.
C50: Model completed 9/3/2026 by Tyler Spencer using data available as of 3/1/2023. Uploaded source filings: Regal Rexnord 2022 10-K, Altra 2022 10-K, Regal Rexnord Q4 2022 earnings release (2/1/2023), Altra Q4 & FY2022 earnings release (3/1/2023).
